Workbook

Sheet Ativo
A1: Cod_tipo | B1: Tipo | C1: Cod_grupo | D1: Grupo | E1: cod_Nivel | F1: Nivel | G1: Cod_nivel 2 | H1: Nivel 2 | I1: Ordem | J1: Descricao | K1: 46142 | L1: 46022 | M1: 45657 | N1: 45291 | O1: 44926 | P1: 44561 | Q1: 44196 | R1: 43830 | S1: 43465
A2: 1 | B2: Ativo | C2: 1 | D2: Ativo Circulante | E2: 1 | F2: Ativo Circulante | G2: 1 | H2: Caixa e Equivalentes de Caixa | I2: 1 | J2: Disponível | K2: =SUMIFS(Planilha1!G:G,Planilha1!H:H,Ativo!G:G,Planilha1!I:I,Ativo!H:H)/1000 -> 1038.0577 | L2: 5300.9863 | M2: 2726.8522 | N2: 5871.2931 | O2: 901.73356 | P2: 4492.643 | Q2: 7721.5331 | R2: 1809.555 | S2: 5667.0328
A3: 1 | B3: Ativo | C3: 1 | D3: Ativo Circulante | E3: 1 | F3: Ativo Circulante | G3: 2 | H3: Contas a Receber - Clientes | I3: 2 | J3: Contas a receber | K3: =SUMIFS(Planilha1!G:G,Planilha1!H:H,Ativo!G:G,Planilha1!I:I,Ativo!H:H)/1000 -> 5547.969 | L3: 7292.1314 | M3: 11537.635 | N3: 4665.3805 | O3: 5121.8416 | P3: 6075.9538 | Q3: 6021.6186 | R3: 4603.6862 | S3: 28561.788
A4: 1 | B4: Ativo | C4: 1 | D4: Ativo Circulante | E4: 1 | F4: Ativo Circulante | G4: 3 | H4: Adiantamento a Fornecedores | I4: 3 | J4: Adiantamentos concedidos | K4: =SUMIFS(Planilha1!G:G,Planilha1!H:H,Ativo!G:G,Planilha1!I:I,Ativo!H:H)/1000 -> 2413.327 | L4: 1832.7243 | M4: 3276.8184 | N4: 2676.4235 | O4: 3488.9931 | P4: 4190.2612 | Q4: 3216.3854 | R4: 2792.8916 | S4: 10119.588
A5: 1 | B5: Ativo | C5: 1 | D5: Ativo Circulante | E5: 1 | F5: Ativo Circulante | G5: 4 | H5: Tributos a Recuperar | I5: 4 | J5: Impostos recuperáveis | K5: =SUMIFS(Planilha1!G:G,Planilha1!H:H,Ativo!G:G,Planilha1!I:I,Ativo!H:H)/1000 -> 31179.367 | L5: 35417.009 | M5: 30977.861 | N5: 30044.277 | O5: 26078.627 | P5: 20550.263 | Q5: 15372.856 | R5: 10290.206 | S5: =9210.56336+174 -> 9384.5634
A6: 1 | B6: Ativo | C6: 1 | D6: Ativo Circulante | E6: 1 | F6: Ativo Circulante | G6: 5 | H6: Outros Créditos | I6: 5 | J6: Desconto Celular | N6: 0 | O6: 133.5702 | P6: 0 | Q6: 0 | R6: 0 | S6: 0
A7: 1 | B7: Ativo | C7: 1 | D7: Ativo Circulante | E7: 1 | F7: Ativo Circulante | G7: 5 | H7: Outros Créditos | I7: 5 | J7: Bens a receber ( mercadorias diversas/bens destinados ao ativo permanente) | K7: =SUMIFS(Planilha1!G:G,Planilha1!H:H,Ativo!G:G,Planilha1!I:I,Ativo!H:H)/1000 -> 327.74103 | L7: 196.27883 | M7: 763.87157 | N7: 22.91813 | O7: 16.62569 | P7: 172.40498 | Q7: 340.70628 | R7: 258.95708 | S7: 228.71869
A8: 1 | B8: Ativo | C8: 1 | D8: Ativo Circulante | E8: 1 | F8: Ativo Circulante | G8: 6 | H8: Estoques | I8: 6 | J8: Estoques | K8: =SUMIFS(Planilha1!G:G,Planilha1!H:H,Ativo!G:G,Planilha1!I:I,Ativo!H:H)/1000 -> 10585.12 | L8: 25946.532 | M8: 30056.867 | N8: 27570.374 | O8: 28253.053 | P8: 30265.056 | Q8: 21427.564 | R8: 15134.979 | S8: 6923.6393
A9: 1 | B9: Ativo | C9: 1 | D9: Ativo Circulante | E9: 1 | F9: Ativo Circulante | G9: 7 | H9: Despesas do Exercício Seguinte | I9: 7 | J9: Apontamentos Ind. Agr. Impostos( IPVA/IPTU) / Seguros gerais | N9: 0 | O9: 0 | P9: 9093.5359 | Q9: 4474.3598 | R9: 3443.686 | S9: 3344.3151
A10: 1 | B10: Ativo | C10: 1 | D10: Ativo Circulante | E10: 1 | F10: Ativo Circulante | G10: 7 | H10: Despesas do Exercício Seguinte | I10: 7 | J10: Impostos( IPVA/IPTU) / Seguros gerais | K10: =SUMIFS(Planilha1!G:G,Planilha1!H:H,Ativo!G:G,Planilha1!I:I,Ativo!H:H)/1000 -> 6906.5943 | L10: 14416.256 | M10: 9305.6116 | N10: 47.04967 | O10: 54.66064 | P10: 0 | Q10: 0 | R10: 0 | S10: 0
A11: 1 | B11: Ativo | C11: 1 | D11: Ativo Circulante | E11: 1 | F11: Ativo Circulante | G11: 8 | H11: Ativo Biológico | I11: 8 | J11: Tratos culturais / ajuste ativo biologico | K11: =SUMIFS(Planilha1!G:G,Planilha1!H:H,Ativo!G:G,Planilha1!I:I,Ativo!H:H)/1000 -> 28380.459 | L11: 28034.082 | M11: 35758.57 | N11: 41037.293 | O11: 43117.355 | P11: 27558.023 | Q11: 16102.513 | R11: 6210.7463 | S11: 3433.463
A12: 1 | B12: Ativo | C12: 1 | D12: Ativo Circulante | E12: 1 | F12: Ativo Circulante | G12: 9 | H12: Depositos Judiciais | I12: 9 | J12: Engenharq/prefeitura rio largo/ creditos lei 4870 | K12: =SUMIFS(Planilha1!G:G,Planilha1!H:H,Ativo!G:G,Planilha1!I:I,Ativo!H:H)/1000 -> 12681.464 | L12: 12681.464 | M12: 11926.402 | N12: 19196.655 | O12: 18305.59 | P12: 13426.051 | Q12: 13279.395 | R12: 0 | S12: 0
A13: 1 | B13: Ativo | C13: 2 | D13: Não Circulante | E13: 2 | F13: Realizável a Longo Prazo | G13: 10 | H13: Transações com Partes Relacionadas | I13: 10 | J13: Transações com Partes Relacionadas | K13: =SUMIFS(Planilha1!G:G,Planilha1!H:H,Ativo!G:G,Planilha1!I:I,Ativo!H:H)/1000 -> 7133.2548 | L13: 7133.2548 | M13: 2409.9649 | N13: 301.35162 | O13: 1020 | P13: 8513.4036 | Q13: 9905.9505 | R13: 9905.9505 | S13: 9657.2369
A14: 1 | B14: Ativo | C14: 2 | D14: Não Circulante | E14: 2 | F14: Realizável a Longo Prazo | G14: 11 | H14: Depositos Judiciais | I14: 11 | J14: Depositos Trabalhistas/Civis/Tributários | K14: =SUMIFS(Planilha1!G:G,Planilha1!H:H,Ativo!G:G,Planilha1!I:I,Ativo!H:H)/1000 -> 586.04924 | L14: 548.02873 | M14: 504.30426 | N14: 639.83647 | O14: 451.18841 | P14: 228.58744 | Q14: 202.59042 | R14: 152.80208 | S14: 35.17346
A15: 1 | B15: Ativo | C15: 2 | D15: Não Circulante | E15: 2 | F15: Realizável a Longo Prazo | G15: 12 | H15: Tributos a Recuperar | I15: 12 | J15: Pedido de Ressarcimento - IPI | K15: =SUMIFS(Planilha1!G:G,Planilha1!H:H,Ativo!G:G,Planilha1!I:I,Ativo!H:H)/1000 -> 0 | L15: 0 | M15: 0 | O15: 0 | P15: 0 | Q15: 7473.3843 | R15: 7473.3843 | S15: 7473.3843
A16: 1 | B16: Ativo | C16: 2 | D16: Não Circulante | E16: 2 | F16: Realizável a Longo Prazo | G16: 13 | H16: Outros Créditos | I16: 13 | J16: Contas a Receber L.P | K16: =SUMIFS(Planilha1!G:G,Planilha1!H:H,Ativo!G:G,Planilha1!I:I,Ativo!H:H)/1000 -> 45.70927 | L16: 45.70927 | M16: 45.70927 | O16: 0 | P16: 0 | Q16: 1270.2802 | R16: 1270.2802 | S16: 1270.2802
A17: 1 | B17: Ativo | C17: 2 | D17: Não Circulante | E17: 3 | F17: Investimentos | G17: 14 | H17: Investimentos | I17: 14 | J17: Participações em outras empresas | K17: =SUMIFS(Planilha1!G:G,Planilha1!H:H,Ativo!G:G,Planilha1!I:I,Ativo!H:H)/1000 -> 9540.8484 | L17: 19630.318 | M17: 14821.018 | N17: 11375.293 | O17: 9541 | P17: 287.62949 | Q17: 16946.514 | R17: 16946.514 | S17: 16946.514
A18: 1 | B18: Ativo | C18: 2 | D18: Não Circulante | E18: 4 | F18: Imobilizado | G18: 15 | H18: Imobilizado | I18: 15 | J18: Imobilizado | K18: =SUMIFS(Planilha1!G:G,Planilha1!H:H,Ativo!G:G,Planilha1!I:I,Ativo!H:H)/1000 -> 177930.67 | L18: 177797.31 | M18: 188499.75 | N18: 158670.3 | O18: 150501.01 | P18: 131400.19 | Q18: 113031.69 | R18: 100460.31 | S18: 90783.303

Sheet passivo
A1: Cod_tipo | B1: Tipo | C1: Cod_grupo | D1: Grupo | E1: cod_Nivel | F1: Nivel | G1: Cod_nivel 2 | H1: Nivel 2 | I1: Ordem | J1: Descricao | K1: 46142 | L1: 46022 | M1: 45657 | N1: 45291 | O1: 44926 | P1: 44561 | Q1: 44196 | R1: 43830 | S1: 43465
A2: 2 | B2: Passivo | C2: 1 | D2: Passivo Circulante | E2: 1 | F2: Passivo Circulante | G2: 1 | H2: Empréstimos e financiamentos | I2: 1 | J2: Daycoval/Raizen | K2: =-SUMIFS(Planilha1!G:G,Planilha1!H:H,passivo!I2,Planilha1!I:I,passivo!J2)/1000 -> 2224.5227 | L2: 2102.8281 | M2: 1709.8331 | N2: 966.11773 | O2: 44.1554 | P2: 254.81868 | Q2: 0 | R2: 71.38196 | S2: 181.73491
A3: 2 | B3: Passivo | C3: 1 | D3: Passivo Circulante | E3: 1 | F3: Passivo Circulante | G3: 1 | H3: Empréstimos e financiamentos | I3: 1 | J3: Raizen | K3: =-SUMIFS(Planilha1!G:G,Planilha1!H:H,passivo!I3,Planilha1!I:I,passivo!J3)/1000 -> 0 | L3: 0 | M3: 0 | N3: 0 | O3: 0 | P3: 0 | Q3: 0 | R3: 0 | S3: 0
A4: 2 | B4: Passivo | C4: 1 | D4: Passivo Circulante | E4: 1 | F4: Passivo Circulante | G4: 1 | H4: Empréstimos e financiamentos | I4: 1 | J4: Sucres | K4: =-SUMIFS(Planilha1!G:G,Planilha1!H:H,passivo!I4,Planilha1!I:I,passivo!J4)/1000 -> 9977.2 | L4: 11003.6 | M4: 0 | N4: 0 | O4: 0 | P4: 0 | Q4: 0 | R4: 0 | S4: 0
A5: 2 | B5: Passivo | C5: 1 | D5: Passivo Circulante | E5: 1 | F5: Passivo Circulante | G5: 2 | H5: Fornecedores | I5: 2 | J5: Fornecedores Diversos | K5: =-SUMIFS(Planilha1!G:G,Planilha1!H:H,passivo!I5,Planilha1!I:I,passivo!J5)/1000 -> 41696.171 | L5: 49552.034 | M5: 52341.678 | N5: 24287.037 | O5: 26824.091 | P5: 17365.34 | Q5: 54414.104 | R5: 50425.459 | S5: 53420.366
A6: 2 | B6: Passivo | C6: 1 | D6: Passivo Circulante | E6: 1 | F6: Passivo Circulante | G6: 3 | H6: Impostos taxas e Contribuições Diversas | I6: 3 | J6: Impostos taxas e contribuições | K6: =-SUMIFS(Planilha1!G:G,Planilha1!H:H,passivo!I6,Planilha1!I:I,passivo!J6)/1000 -> 600.80933 | L6: 4070.6261 | M6: 3479.3739 | N6: 20962.112 | O6: 21242.189 | P6: 137684.13 | Q6: 140208.34 | R6: 123209.6 | S6: 116899.46
A7: 2 | B7: Passivo | C7: 1 | D7: Passivo Circulante | E7: 1 | F7: Passivo Circulante | G7: 3 | H7: Impostos taxas e Contribuições Diversas | I7: 3 | J7: Encargos tributários | K7: =-SUMIFS(Planilha1!G:G,Planilha1!H:H,passivo!I7,Planilha1!I:I,passivo!J7)/1000 -> 228.50876 | L7: 702.75864 | M7: 776.47263 | N7: 766.14696 | O7: 555.98984 | P7: 1824.7661 | Q7: 1226.9216 | R7: 1013.4658 | S7: 1022.917
A8: 2 | B8: Passivo | C8: 1 | D8: Passivo Circulante | E8: 1 | F8: Passivo Circulante | G8: 4 | H8: Salarios e provisão de férias | I8: 4 | J8: Salarioa a pagar | K8: =-SUMIFS(Planilha1!G:G,Planilha1!H:H,passivo!I8,Planilha1!I:I,passivo!J8)/1000 -> 1922.6115 | L8: 5613.3569 | M8: 5196.9168 | N8: 6458.2818 | O8: 6086.367 | P8: 4951.1398 | Q8: 17552.415 | R8: 17216.831 | S8: 16802.4
A9: 2 | B9: Passivo | C9: 1 | D9: Passivo Circulante | E9: 1 | F9: Passivo Circulante | G9: 4 | H9: Salarios e provisão de férias | I9: 4 | J9: Provisões | K9: =-SUMIFS(Planilha1!G:G,Planilha1!H:H,passivo!I9,Planilha1!I:I,passivo!J9)/1000 -> 8042.9865 | L9: 9414.9127 | M9: 9030.215 | N9: 8035.7204 | O9: 6832.4525 | P9: 5870.9302 | Q9: 4725.8314 | R9: 4249.2401 | S9: 3662.4923
A10: 2 | B10: Passivo | C10: 1 | D10: Passivo Circulante | E10: 1 | F10: Passivo Circulante | G10: 4 | H10: Salarios e provisão de férias | I10: 4 | J10: Acordos Judiciais | K10: =-SUMIFS(Planilha1!G:G,Planilha1!H:H,passivo!I10,Planilha1!I:I,passivo!J10)/1000 -> 0 | L10: 0 | M10: 0 | Q10: 15137.352 | R10: 15137.352 | S10: 13417.095
A11: 2 | B11: Passivo | C11: 1 | D11: Passivo Circulante | E11: 1 | F11: Passivo Circulante | G11: 5 | H11: Parcelamentos Fiscais | I11: 5 | J11: Parcelamentos Fiscais | K11: =-SUMIFS(Planilha1!G:G,Planilha1!H:H,passivo!I11,Planilha1!I:I,passivo!J11)/1000 -> 19795.166 | L11: 15203.462 | M11: 14229.108 | N11: 12160.308 | O11: 11846.26 | P11: 2846.7082 | Q11: 1843.9204 | R11: 1476.06 | S11: 1419.0265
A12: 2 | B12: Passivo | C12: 1 | D12: Passivo Circulante | E12: 1 | F12: Passivo Circulante | G12: 6 | H12: Adiantamentos de clientes | I12: 6 | J12: Adiantamentos de clientes | K12: =-SUMIFS(Planilha1!G:G,Planilha1!H:H,passivo!I12,Planilha1!I:I,passivo!J12)/1000 -> 54358.927 | L12: 53607.428 | M12: 26596.051 | N12: 22429.354 | O12: 18891.012 | P12: 8774.4515 | Q12: 28975.586 | R12: 12145.485 | S12: 5110.591
A13: 2 | B13: Passivo | C13: 1 | D13: Passivo Circulante | E13: 1 | F13: Passivo Circulante | G13: 7 | H13: Credores sob contrato | I13: 7 | J13: Raizen | K13: =-SUMIFS(Planilha1!G:G,Planilha1!H:H,passivo!I13,Planilha1!I:I,passivo!J13)/1000 -> -2018.362 | L13: -1496.5287 | M13: -175.08927 | N13: -168.49994 | O13: 75 | P13: 75 | Q13: 1178.7379 | R13: 3906.25 | S13: 10205
A14: 2 | B14: Passivo | C14: 1 | D14: Passivo Circulante | E14: 1 | F14: Passivo Circulante | G14: 7 | H14: Credores sob contrato | I14: 7 | J14: ACL | K14: =-SUMIFS(Planilha1!G:G,Planilha1!H:H,passivo!I14,Planilha1!I:I,passivo!J14)/1000 -> 10525.668 | L14: 5220 | M14: 3648 | N14: 2780.675
A15: 2 | B15: Passivo | C15: 1 | D15: Passivo Circulante | E15: 1 | F15: Passivo Circulante | G15: 8 | H15: Outras contas a pagar | I15: 8 | J15: Credores diversos | K15: =-SUMIFS(Planilha1!G:G,Planilha1!H:H,passivo!I15,Planilha1!I:I,passivo!J15)/1000 -> 497.60205 | L15: 347.96711 | M15: 464.86736 | N15: 354.21835 | O15: 310.39648 | P15: 221.52221 | Q15: 3183.4719 | R15: 5401.6705 | S15: 5296.4326
A16: 2 | B16: Passivo | C16: 1 | D16: Passivo Circulante | E16: 1 | F16: Passivo Circulante | G16: 8 | H16: Outras contas a pagar | I16: 8 | J16: Emprestimos de mercadorias | K16: =-SUMIFS(Planilha1!G:G,Planilha1!H:H,passivo!I16,Planilha1!I:I,passivo!J16)/1000 -> 0 | L16: 0 | M16: 2072.5644 | N16: 442.0305 | O16: 457.16663 | P16: 181.0693 | Q16: 508.93398 | R16: 344.86936 | S16: 384.42236
A17: 2 | B17: Passivo | C17: 1 | D17: Passivo Circulante | E17: 1 | F17: Passivo Circulante | G17: 8 | H17: Provisão Para Perdas | I17: 8 | J17: Operações Financeiras | K17: =-SUMIFS(Planilha1!G:G,Planilha1!H:H,passivo!I17,Planilha1!I:I,passivo!J17)/1000 -> 0 | L17: 0 | M17: 222.3 | N17: 442.0305 | O17: 457.16663 | P17: 181.0693 | Q17: 508.93398 | R17: 344.86936 | S17: 384.42236
A18: 2 | B18: Passivo | C18: 1 | D18: Passivo Circulante | E18: 1 | F18: Passivo Circulante | G18: 9 | H18: Dividendos a Distribuir Proposto | I18: 9 | J18: Dividendos a Distribuir Proposto | K18: =-SUMIFS(Planilha1!G:G,Planilha1!H:H,passivo!I18,Planilha1!I:I,passivo!J18)/1000 -> 633.89326 | L18: 633.89326 | M18: 0 | N18: 0 | O18: 0 | P18: 0 | Q18: 0 | R18: 0 | S18: 0
A19: 2 | B19: Passivo | C19: 1 | D19: Passivo Circulante | E19: 1 | F19: Passivo Circulante | G19: 24 | H19: Adiantamentos De dividendos | I19: 24 | J19: Adiantamentos De dividendos | K19: =-SUMIFS(Planilha1!G:G,Planilha1!H:H,passivo!I19,Planilha1!I:I,passivo!J19)/1000 -> 15108.03
A20: 2 | B20: Passivo | C20: 2 | D20: Não Circulante | E20: 2 | F20: Passivo Não Circulante | G20: 10 | H20: Empréstimos e financiamentos. | I20: 10 | J20: Empréstimos e financiamentos | K20: =-SUMIFS(Planilha1!G:G,Planilha1!H:H,passivo!I20,Planilha1!I:I,passivo!J20)/1000 -> 12371.103 | L20: 25012.339 | M20: 3800.3996 | N20: 1915.3724 | O20: 0 | P20: 44.15542 | Q20: 84703.132 | R20: 84703.132 | S20: 84703.132
A21: 2 | B21: Passivo | C21: 2 | D21: Não Circulante | E21: 2 | F21: Passivo Não Circulante | G21: 11 | H21: Fornecedores. | I21: 11 | J21: Fornecedores diversos | K21: =-SUMIFS(Planilha1!G:G,Planilha1!H:H,passivo!I21,Planilha1!I:I,passivo!J21)/1000 -> 0 | L21: 0 | M21: 0 | O21: 0 | P21: 0 | Q21: 3185.0166 | R21: 3185.0166 | S21: 3185.0166
A22: 2 | B22: Passivo | C22: 2 | D22: Não Circulante | E22: 2 | F22: Passivo Não Circulante | G22: 12 | H22: Cooperativa conta corrente | I22: 12 | J22: Cooperativa conta corrente | K22: =-SUMIFS(Planilha1!G:G,Planilha1!H:H,passivo!I22,Planilha1!I:I,passivo!J22)/1000 -> 0 | L22: 0 | M22: 0 | O22: 0 | P22: 0 | Q22: 13341.994 | R22: 13341.994 | S22: 13341.994
A23: 2 | B23: Passivo | C23: 2 | D23: Não Circulante | E23: 2 | F23: Passivo Não Circulante | G23: 13 | H23: Parcelamento fiscais | I23: 13 | J23: Parcelamento fiscais | K23: =-SUMIFS(Planilha1!G:G,Planilha1!H:H,passivo!I23,Planilha1!I:I,passivo!J23)/1000 -> 85398.207 | L23: 90423.049 | M23: 88663.413 | N23: 91386.028 | O23: 92661.622 | P23: 7820.1922 | Q23: 5278.5685 | R23: 5723.9424 | S23: 6984.5272
A24: 2 | B24: Passivo | C24: 2 | D24: Não Circulante | E24: 2 | F24: Passivo Não Circulante | G24: 14 | H24: Provisão para perda de investimentos | I24: 14 | J24: Provisão para perda de investimentos | K24: =-SUMIFS(Planilha1!G:G,Planilha1!H:H,passivo!I24,Planilha1!I:I,passivo!J24)/1000 -> 0 | L24: 0 | M24: 0 | O24: 0 | P24: 16117.194 | Q24: 16117.194 | R24: 16117.194 | S24: 16117.194
A25: 2 | B25: Passivo | C25: 2 | D25: Não Circulante | E25: 2 | F25: Passivo Não Circulante | G25: 15 | H25: Credores sob contrato. | I25: 15 | J25: Raizen | K25: =-SUMIFS(Planilha1!G:G,Planilha1!H:H,passivo!I25,Planilha1!I:I,passivo!J25)/1000 -> 0 | L25: 0 | M25: 0 | N25: 200 | O25: 237.5 | P25: 312.5 | Q25: 0 | R25: 0 | S25: 0
A26: 2 | B26: Passivo | C26: 2 | D26: Não Circulante | E26: 2 | F26: Passivo Não Circulante | G26: 16 | H26: Partes relacionadas | I26: 16 | J26: Mundau agro pecuaria | K26: =-SUMIFS(Planilha1!G:G,Planilha1!H:H,passivo!I26,Planilha1!I:I,passivo!J26)/1000 -> 0 | L26: 3403.578 | M26: 78.16 | N26: 78.16 | O26: 78.16 | P26: 78.16 | Q26: 2222.7083 | R26: 3225.7703 | S26: 4133
A27: 2 | B27: Passivo | C27: 2 | D27: Não Circulante | E27: 2 | F27: Passivo Não Circulante | G27: 17 | H27: Impostos taxas e Contribuições Diversas. | I27: 17 | J27: Encargos tributários | K27: =-SUMIFS(Planilha1!G:G,Planilha1!H:H,passivo!I27,Planilha1!I:I,passivo!J27)/1000 -> 12853.083 | L27: 12853.083 | M27: 12853.083 | N27: 766.14696 | O27: 555.98984 | P27: 1824.7661 | Q27: 1226.9216 | R27: 1013.4658 | S27: 1022.917
A28: 2 | B28: Passivo | C28: 2 | D28: Não Circulante | E28: 2 | F28: Passivo Não Circulante | G28: 18 | H28: Operações Financeiras - NDF | I28: 18 | J28: Operações Financeiras | K28: =-SUMIFS(Planilha1!G:G,Planilha1!H:H,passivo!I28,Planilha1!I:I,passivo!J28)/1000 -> 0 | L28: 0 | M28: 0
A29: 2 | B29: Passivo | C29: 2 | D29: Não Circulante | E29: 2 | F29: Passivo Não Circulante | G29: 19 | H29: Credores recuperação judicial | I29: 19 | J29: Credores recuperação judicial | K29: =-SUMIFS(Planilha1!G:G,Planilha1!H:H,passivo!I29,Planilha1!I:I,passivo!J29)/1000 -> 35353.052 | L29: 36061.335 | M29: 37309.525 | N29: 44173.626 | O29: 46140.944 | P29: 49120.545 | Q29: 0 | R29: 0 | S29: 0
A30: 2 | B30: Passivo | C30: 2 | D30: Não Circulante | E30: 2 | F30: Passivo Não Circulante | G30: 20 | H30: Provisão para Contigências | I30: 20 | J30: Provisão para Contigências | K30: =-SUMIFS(Planilha1!G:G,Planilha1!H:H,passivo!I30,Planilha1!I:I,passivo!J30)/1000 -> 0 | L30: 0 | M30: 0 | S30: 1203
A31: 2 | B31: Passivo | C31: 2 | D31: Não Circulante | E31: 2 | F31: Passivo Não Circulante | G31: 24 | H31: Provisão Para Perdas | I31: 24 | J31: Provisão Para Perdas | K31: =-SUMIFS(Planilha1!G:G,Planilha1!H:H,passivo!I31,Planilha1!I:I,passivo!J31)/1000 -> 366.03384 | L31: 366.03384 | M31: 456.62067 | S31: 1203
A32: 2 | B32: Passivo | C32: 3 | D32: Patrimônio líquido | E32: 3 | F32: Patrimônio líquido | G32: 21 | H32: Capital social | I32: 21 | J32: Capital social | K32: =-SUMIFS(Planilha1!G:G,Planilha1!H:H,passivo!I32,Planilha1!I:I,passivo!J32)/1000 -> 58212.262 | L32: 58212.262 | M32: 58212.262 | N32: 58212.262 | O32: 58212.262 | P32: 58212.262 | Q32: 58212.262 | R32: 58212.262 | S32: 58212.262
A33: 2 | B33: Passivo | C33: 3 | D33: Patrimônio líquido | E33: 3 | F33: Patrimônio líquido | G33: 22 | H33: Reserva de lucro | I33: 22 | J33: Reservas | K33: =-SUMIFS(Planilha1!G:G,Planilha1!H:H,passivo!I33,Planilha1!I:I,passivo!J33)/1000 -> 21011.584 | L33: 0 | M33: =6679.49784+14965.97974 -> 21645.478 | N33: 6679.4978 | O33: 0 | P33: 5.74843 | Q33: 5.74843 | R33: 5.74843 | S33: 5.74843
A34: 2 | B34: Passivo | C34: 3 | D34: Patrimônio líquido | E34: 3 | F34: Patrimônio líquido | G34: 23 | H34: Prejuízos acumulados | I34: 23 | J34: Lucros/Prejuizos acumulados | K34: =-SUMIFS(Planilha1!G:G,Planilha1!H:H,passivo!I34,Planilha1!I:I,passivo!J34)/1000 -> -67047.517 | L34: 0 | M34: 0 | N34: -10189.739 | O34: -39383.782 | P34: -222708.28 | Q34: -238358.77 | R34: -221879.05 | S34: =-212352.00097+173.456 -> -212178.54
A35: 2 | B35: Passivo | C35: 3 | D35: Patrimônio líquido | E35: 3 | F35: Patrimônio líquido | G35: 23 | H35: Prejuízos acumulados | I35: 23 | J35: Resultado do exercício | K35: =-SUMIFS(Planilha1!G:G,Planilha1!H:H,passivo!I35,Planilha1!I:I,passivo!J35)/1000 -> -27814.909 | L35: -46035.933 | M35: 0 | N35: 10189.739 | O35: 35873.444 | P35: 167201.65 | Q35: 23123.879 | R35: -16479.725 | S35: =-9700.68888 -> -9700.6889

Sheet TESTE
B1: ATIVO | C1: PASSIVO | D1: DIFERENÇA
B2: =SUM(Ativo!K2:K52) -> 294296.63 | C2: =SUM(passivo!K2:K95) -> 294296.63 | D2: =B2-C2 -> 0 | F2: =D2*1000 -> 0
B3: =SUMIF(Planilha1!A:A,1,Planilha1!G:G)/1000 -> 294296.63 | C3: =-SUMIF(Planilha1!A:A,2,Planilha1!G:G)/1000-SUMIF(Planilha1!A:A,3,Planilha1!G:G)/1000 -> 294296.63 | D3: =B3-C3 -> 0 | F3: =D3*1000 -> 0
B4: =IF(ROUND(B2-B3,2)=0,"ESTAR CERTO","ESTAR ERRADO") -> ESTAR CERTO | C4: =IF(ROUND(C2-C3,2)=0,"ESTAR CERTO","ESTAR ERRADO") -> ESTAR CERTO
B5: =B2-B3 -> 0 | C5: =C2-C3 -> 0
B7: ATIVO CIRCULANTE | C7: PASSIVO CIRCULANTE
B8: =SUM(Ativo!K2:K12) -> 99060.1 | C8: =SUM(passivo!K2:K19) -> 163593.73 | D8: =C8-C9 -> 0
B9: =SUMIF(Planilha1!A:A, " 1.1",Planilha1!G:G)/1000 -> 99060.1 | C9: =-SUMIF(Planilha1!A:A, " 2.1",Planilha1!G:G)/1000 -> 163593.73
B10: =IF(ROUND(B8-B9,2)=0,"ESTAR CERTO","ESTAR ERRADO") -> ESTAR CERTO | C10: =IF(ROUND(C8-C9,2)=0,"ESTAR CERTO","ESTAR ERRADO") -> ESTAR CERTO
B12: ATIVO REALIZAVEL A LONGO PRAZO | C12: PASSIVO Ñ CIRCULANTE
B13: =SUM(Ativo!K13:K16) -> 7765.0134 | C13: =SUM(passivo!K20:K31) -> 146341.48
B14: =SUMIF(Planilha1!A:A, " 1.2",Planilha1!G:G)/1000 -> 7765.0134 | C14: =-SUMIF(Planilha1!A:A, " 2.2",Planilha1!G:G)/1000 -> 146341.48
B15: =IF(ROUND(B13-B14,2)=0,"ESTAR CERTO","ESTAR ERRADO") -> ESTAR CERTO | C15: =IF(ROUND(C13-C14,2)=0,"ESTAR CERTO","ESTAR ERRADO") -> ESTAR CERTO
B17: INVESTIMENTO | C17: RESULTADO
B18: =Ativo!K17 -> 9540.8484 | C18: =SUM(passivo!K32:K35) -> -15638.58 | D18: =C18-C19 -> 0
B19: =SUMIF(Planilha1!A:A, " 1.3.1",Planilha1!G:G)/1000 -> 9540.8484 | C19: =-SUMIF(Planilha1!A:A," 2.4",Planilha1!G:G)/1000-SUMIF(Planilha1!A:A," 3",Planilha1!G:G)/1000 -> -15638.58
B20: =IF(ROUND(B18-B19,2)=0,"ESTAR CERTO","ESTAR ERRADO") -> ESTAR CERTO | C20: =IF(ROUND(C18-C19,2)=0,"ESTAR CERTO","ESTAR ERRADO") -> ESTAR CERTO
B22: IMOBILIZADO
B23: =Ativo!K18 -> 177930.67
B24: =SUMIF(Planilha1!A:A, " 1.3.2",Planilha1!G:G)/1000 -> 177930.67
B25: =IF(ROUND(B23-B24,2)=0,"ESTAR CERTO","ESTAR ERRADO") -> ESTAR CERTO

Sheet Planilha1
A1: Balancete - Padrão - Fiscal
A2: Grupo Empresa: 1 - Santa Clotilde | G2: Data: 02/06/2026
A3: Empresa: 1 - USINA SANTA CLOTILDE | G3: Hora: 13:30:20
A4: Filial: 1 - USINA SANTA CLOTILDE S/A | G4: Form: 1016
A5: Mês: 04 - Ano: 2026
A6: Conta contábil: 0 à 0
A7: Conta | B7: Descrição | C7: Saldo Anterior | D7: Débitos | E7: Créditos | F7: Saldo Mensal | G7: Saldo
A8: 1 | B8: ATIVO | C8: 2.9996597e+08 | D8: 44425822 | E8: 50095155 | F8: -5669333.8 | G8: 2.9429663e+08 | H8: =_xlfn.XLOOKUP(A8,indice!A:A,indice!C:C) -> S | I8: =_xlfn.XLOOKUP(A8,indice!A:A,indice!D:D) -> SINTETICA
A9: 1.1 | B9: ATIVO CIRCULANTE | C9: 1.0414344e+08 | D9: 43560472 | E9: 48643814 | F9: -5083342.4 | G9: 99060100 | H9: =_xlfn.XLOOKUP(A9,indice!A:A,indice!C:C) -> S | I9: =_xlfn.XLOOKUP(A9,indice!A:A,indice!D:D) -> SINTETICA
A10: 1.1.1 | B10: DISPONÍVEL | C10: 4568955.3 | D10: 17198462 | E10: 20729360 | F10: -3530897.6 | G10: 1038057.7 | H10: =_xlfn.XLOOKUP(A10,indice!A:A,indice!C:C) -> S | I10: =_xlfn.XLOOKUP(A10,indice!A:A,indice!D:D) -> SINTETICA
A11: 1.1.1.01 | B11: CAIXA | C11: 82459.39 | D11: 7346291.2 | E11: 7334270.2 | F11: 12020.91 | G11: 94480.3 | H11: =_xlfn.XLOOKUP(A11,indice!A:A,indice!C:C) -> S | I11: =_xlfn.XLOOKUP(A11,indice!A:A,indice!D:D) -> SINTETICA
A12: 1.1.1.01.001 | B12: CAIXA AGRÍCOLA | C12: 2991.57 | D12: 2914.16 | E12: 0 | F12: 2914.16 | G12: 5905.73 | H12: =_xlfn.XLOOKUP(A12,indice!A:A,indice!C:C) -> 1 | I12: =_xlfn.XLOOKUP(A12,indice!A:A,indice!D:D) -> Caixa e Equivalentes de Caixa
A13: 1.1.1.01.002 | B13: CAIXA INDÚSTRIA | C13: 2004.71 | D13: 1000.06 | E13: 0 | F13: 1000.06 | G13: 3004.77 | H13: =_xlfn.XLOOKUP(A13,indice!A:A,indice!C:C) -> 1 | I13: =_xlfn.XLOOKUP(A13,indice!A:A,indice!D:D) -> Caixa e Equivalentes de Caixa
A14: 1.1.1.01.003 | B14: CAIXA ADM. CENTRAL | C14: 76463.11 | D14: 25300 | E14: 17193.31 | F14: 8106.69 | G14: 84569.8 | H14: =_xlfn.XLOOKUP(A14,indice!A:A,indice!C:C) -> 1 | I14: =_xlfn.XLOOKUP(A14,indice!A:A,indice!D:D) -> Caixa e Equivalentes de Caixa
A15: 1.1.1.01.005 | B15: CONTA - TRANSITORIO | C15: 0 | D15: 7317076.9 | E15: 7317076.9 | F15: 0 | G15: 0 | H15: =_xlfn.XLOOKUP(A15,indice!A:A,indice!C:C) -> 1 | I15: =_xlfn.XLOOKUP(A15,indice!A:A,indice!D:D) -> Caixa e Equivalentes de Caixa
A16: 1.1.1.01.006 | B16: CAIXA ADM. RH | C16: 1000 | D16: 0 | E16: 0 | F16: 0 | G16: 1000 | H16: =_xlfn.XLOOKUP(A16,indice!A:A,indice!C:C) -> 1 | I16: =_xlfn.XLOOKUP(A16,indice!A:A,indice!D:D) -> Caixa e Equivalentes de Caixa
A17: 1.1.1.02 | B17: BANCO C/MOVIMENTO | C17: 3571595.6 | D17: 9753607.8 | E17: 13136908 | F17: -3383299.9 | G17: 188295.65 | H17: =_xlfn.XLOOKUP(A17,indice!A:A,indice!C:C) -> S | I17: =_xlfn.XLOOKUP(A17,indice!A:A,indice!D:D) -> SINTETICA
A18: 1.1.1.02.001 | B18: CAIXA ECONÔMICA FEDERAL C/C 231-3 | C18: 3488940.1 | D18: 8853346.1 | E18: 12241693 | F18: -3388347.2 | G18: 100592.94 | H18: =_xlfn.XLOOKUP(A18,indice!A:A,indice!C:C) -> 1 | I18: =_xlfn.XLOOKUP(A18,indice!A:A,indice!D:D) -> Caixa e Equivalentes de Caixa
A19: 1.1.1.02.010 | B19: BANCO BRADESCO - C/C 85000-4 | C19: 5731.3 | D19: 1.3 | E19: 325.35 | F19: -324.05 | G19: 5407.25 | H19: =_xlfn.XLOOKUP(A19,indice!A:A,indice!C:C) -> 1 | I19: =_xlfn.XLOOKUP(A19,indice!A:A,indice!D:D) -> Caixa e Equivalentes de Caixa
... A202: 1.3.2.08.027 | B202: DEPRECIAÇÃO DA LAVOURA (SAFRA 2025/2026) | C202: -5424977.4 | D202: 0 | E202: 0 | F202: 0 | G202: -5424977.4 | H202: =_xlfn.XLOOKUP(A202,indice!A:A,indice!C:C) -> 15 | I202: =_xlfn.XLOOKUP(A202,indice!A:A,indice!D:D) -> Imobilizado
A203: 1.3.2.08.090 | B203: AJUSTE DEPRECIAÇÃO SOC-FISCAL | C203: 3166508.4 | D203: 0 | E203: 0 | F203: 0 | G203: 3166508.4 | H203: =_xlfn.XLOOKUP(A203,indice!A:A,indice!C:C) -> 15 | I203: =_xlfn.XLOOKUP(A203,indice!A:A,indice!D:D) -> Imobilizado | J203: =G203 -> 3166508.4
A204: 2 | B204: PASSIVO | C204: -3.252675e+08 | D204: 35680928 | E204: 32524973 | F204: 3155955.1 | G204: -3.2211154e+08 | H204: =_xlfn.XLOOKUP(A204,indice!A:A,indice!C:C) -> S | I204: =_xlfn.XLOOKUP(A204,indice!A:A,indice!D:D) -> SINTETICA | J204: =G323 -> -66782783
A205: 2.1 | B205: PASSIVO CIRCULANTE | C205: -1.6512974e+08 | D205: 33859058 | E205: 32323055 | F205: 1536002.6 | G205: -1.6359373e+08 | H205: =_xlfn.XLOOKUP(A205,indice!A:A,indice!C:C) -> S | I205: =_xlfn.XLOOKUP(A205,indice!A:A,indice!D:D) -> SINTETICA
A206: 2.1.1 | B206: OBRIGAÇÕES A PAGAR | C206: -43381347 | D206: 18362310 | E206: 16677134 | F206: 1685176.3 | G206: -41696171 | H206: =_xlfn.XLOOKUP(A206,indice!A:A,indice!C:C) -> S | I206: =_xlfn.XLOOKUP(A206,indice!A:A,indice!D:D) -> SINTETICA
A207: 2.1.1.01 | B207: FORNECEDORES DIVERSOS | C207: -43381347 | D207: 18337310 | E207: 16652134 | F207: 1685176.3 | G207: -41696171 | H207: =_xlfn.XLOOKUP(A207,indice!A:A,indice!C:C) -> S | I207: =_xlfn.XLOOKUP(A207,indice!A:A,indice!D:D) -> SINTETICA
A208: 2.1.1.01.001 | B208: FORNECEDORES DE MATERIAIS E SERVIÇOS | C208: -12616338 | D208: 13305119 | E208: 10871587 | F208: 2433532.7 | G208: -10182805 | H208: =_xlfn.XLOOKUP(A208,indice!A:A,indice!C:C) -> 2 | I208: =_xlfn.XLOOKUP(A208,indice!A:A,indice!D:D) -> Fornecedores Diversos
A209: 2.1.1.01.002 | B209: FORNECEDORES DE FERTILIZANTES E HERBICIDAS | C209: -15930057 | D209: 783650.85 | E209: 2289520.6 | F209: -1505869.8 | G209: -17435926 | H209: =_xlfn.XLOOKUP(A209,indice!A:A,indice!C:C) -> 2 | I209: =_xlfn.XLOOKUP(A209,indice!A:A,indice!D:D) -> Fornecedores Diversos
A210: 2.1.1.01.003 | B210: FORNECEDORES DE SERVIÇOS DE TRANSPORTES | C210: -202393.26 | D210: 363655.8 | E210: 257226.02 | F210: 106429.78 | G210: -95963.48 | H210: =_xlfn.XLOOKUP(A210,indice!A:A,indice!C:C) -> 2 | I210: =_xlfn.XLOOKUP(A210,indice!A:A,indice!D:D) -> Fornecedores Diversos
A211: 2.1.1.01.004 | B211: FORNECEDORES DE CANA-DE-AÇÚCAR | C211: -12209847 | D211: 3884884.4 | E211: 0 | F211: 3884884.4 | G211: -8324962.5 | H211: =_xlfn.XLOOKUP(A211,indice!A:A,indice!C:C) -> 2 | I211: =_xlfn.XLOOKUP(A211,indice!A:A,indice!D:D) -> Fornecedores Diversos
A212: 2.1.1.01.005 | B212: FORNECEDORES - PARC. IMOBILIZADO | C212: -2422712.7 | D212: 0 | E212: 3233800.7 | F212: -3233800.7 | G212: -5656513.4 | H212: =_xlfn.XLOOKUP(A212,indice!A:A,indice!C:C) -> 2 | I212: =_xlfn.XLOOKUP(A212,indice!A:A,indice!D:D) -> Fornecedores Diversos
A213: 2.1.1.07 | B213: CHEQUES A COMPENSAR | C213: 0 | D213: 25000 | E213: 25000 | F213: 0 | G213: 0 | H213: =_xlfn.XLOOKUP(A213,indice!A:A,indice!C:C) -> 9 | I213: =_xlfn.XLOOKUP(A213,indice!A:A,indice!D:D) -> Credores diversos
A214: 2.1.1.07.001 | B214: CHEQUES A COMPENSAR | C214: 0 | D214: 25000 | E214: 25000 | F214: 0 | G214: 0 | H214: =_xlfn.XLOOKUP(A214,indice!A:A,indice!C:C) -> 9 | I214: =_xlfn.XLOOKUP(A214,indice!A:A,indice!D:D) -> Credores diversos
A215: 2.1.2 | B215: OUTRAS OBRIGAÇÕES | C215: -1.211145e+08 | D215: 15496747 | E215: 15645921 | F215: -149173.72 | G215: -1.2126367e+08 | H215: =_xlfn.XLOOKUP(A215,indice!A:A,indice!C:C) -> S | I215: =_xlfn.XLOOKUP(A215,indice!A:A,indice!D:D) -> SINTETICA
A216: 2.1.2.02 | B216: EMPRÉSTIMOS E FINANCIAMENTOS | C216: -12458515 | D216: 1550799 | E216: 1294007 | F216: 256792 | G216: -12201723 | H216: =_xlfn.XLOOKUP(A216,indice!A:A,indice!C:C) -> S | I216: =_xlfn.XLOOKUP(A216,indice!A:A,indice!D:D) -> SINTETICA
... A515: 3.2.3.06.002 | B515: RECEITA DA ALIENAÇÃO DE IMOBILIZADO | C515: -70000 | D515: 0 | E515: 0 | F515: 0 | G515: -70000 | H515: =_xlfn.XLOOKUP(A515,indice!A:A,indice!C:C) -> N | I515: =_xlfn.XLOOKUP(A515,indice!A:A,indice!D:D) -> NÃO UTILIZAR
D516: 1.0100534e+08 | E516: 1.0100534e+08

Sheet indice
A1: Balancete - Padrão - Fiscal
A2: Grupo Empresa: 1 - Santa Clotilde
A3: Empresa: 1 - USINA SANTA CLOTILDE
A4: Filial: 1 - USINA SANTA CLOTILDE S/A
A5: Período: 01/01/2024 à 30/04/2024
A6: Conta contábil: 1 à 0
A8: Conta | B8: Descrição
A9: 1 | B9: ATIVO | C9: S | D9: SINTETICA
A10: 1.1 | B10: ATIVO CIRCULANTE | C10: S | D10: SINTETICA
A11: 1.1.1 | B11: DISPONÍVEL | C11: S | D11: SINTETICA
A12: 1.1.1.01 | B12: CAIXA | C12: S | D12: SINTETICA
A13: 1.1.1.01.001 | B13: CAIXA AGRÍCOLA | C13: 1 | D13: Caixa e Equivalentes de Caixa
A14: 1.1.1.01.002 | B14: CAIXA INDÚSTRIA | C14: 1 | D14: Caixa e Equivalentes de Caixa
A15: 1.1.1.01.003 | B15: CAIXA ADM. CENTRAL | C15: 1 | D15: Caixa e Equivalentes de Caixa
A16: 1.1.1.01.005 | B16: CONTA - TRANSITORIO | C16: 1 | D16: Caixa e Equivalentes de Caixa
A17: 1.1.1.01.006 | B17: CAIXA ADM. RH | C17: 1 | D17: Caixa e Equivalentes de Caixa
A18: 1.1.1.02 | B18: BANCO C/MOVIMENTO | C18: S | D18: SINTETICA
A19: 1.1.1.02.001 | B19: CAIXA ECONÔMICA FEDERAL C/C 231-3 | C19: 1 | D19: Caixa e Equivalentes de Caixa
A20: 1.1.1.02.003 | B20: BIC BANCO - C/C 14100218/7 | C20: 1 | D20: Caixa e Equivalentes de Caixa
A21: 1.1.1.02.007 | B21: BIC BANCO - C/C 42.100219-5 | C21: 1 | D21: Caixa e Equivalentes de Caixa
A22: 1.1.1.02.010 | B22: BANCO BRADESCO - C/C 85000-4 | C22: 1 | D22: Caixa e Equivalentes de Caixa
A23: 1.1.1.02.011 | B23: BANCO DAYCOVAL - C/C 7316552 | C23: 1 | D23: Caixa e Equivalentes de Caixa
A24: 1.1.1.02.013 | B24: BANCO BTG PACTUAL - C/C 1320679 | C24: 1 | D24: Caixa e Equivalentes de Caixa
A25: 1.1.1.02.014 | B25: BANCO DAYCOVAL - C/C 613576-7 | C25: 1 | D25: Caixa e Equivalentes de Caixa
A26: 1.1.1.03 | B26: BANCO C/ APLICAÇÕES FINANCEIRAS | C26: S | D26: SINTETICA
A27: 1.1.1.03.001 | B27: CAIXA ECONÔMICA FEDERAL (RIO LARGO) | C27: 1 | D27: Caixa e Equivalentes de Caixa
A28: 1.1.1.03.007 | B28: BANCO DAYCOVAL C/C 731655 | C28: 1 | D28: Caixa e Equivalentes de Caixa
A29: 1.1.1.05 | B29: INVESTIMENTOS | C29: S | D29: SINTETICA
A30: 1.1.1.05.002 | B30: POUPANÇA CEF - 114 | C30: 1 | D30: Caixa e Equivalentes de Caixa
A31: 1.1.1.05.004 | B31: BTG PACTUAL | C31: 1 | D31: Caixa e Equivalentes de Caixa
A32: 1.1.1.05.006 | B32: CAIXA ECONOMICA FEDERAL | C32: 1 | D32: Caixa e Equivalentes de Caixa
A33: 1.1.2 | B33: CONTAS A RECEBER | C33: S | D33: SINTETICA
A34: 1.1.2.01 | B34: CRÉDITOS A RECEBER | C34: S | D34: SINTETICA
A35: 1.1.2.01.001 | B35: CONTAS A RECEBER | C35: 2 | D35: Contas a Receber - Clientes
A36: 1.1.2.01.998 | B36: (-) PROVISÃO PARA DEVEDORES DUVIDOSOS | C36: 2 | D36: Contas a Receber - Clientes
A37: 1.1.3 | B37: ADIANTAMENTOS CONCEDIDOS | C37: S | D37: SINTETICA
A38: 1.1.3.01 | B38: ADIANTAMENTOS DIVERSOS | C38: S | D38: SINTETICA
A39: 1.1.3.01.001 | B39: ADIANTAMENTOS A FORNEC DE CANA | C39: 3 | D39: Adiantamento a Fornecedores
A40: 1.1.3.01.002 | B40: ADIANTAMENTOS A FORNEC DE MAT, EQUIP. E PROP. | C40: 3 | D40: Adiantamento a Fornecedores
A41: 1.1.3.01.003 | B41: ADIANTAMENTO DA FOLHA DE PAGAMENTO | C41: 3 | D41: Adiantamento a Fornecedores
...
