Workbook

Sheet Export
A1: ORDEM | B1: Item_DRE | C1: 46113 | D1: 46022 | E1: 45657 | F1: 2023 | G1: 2022 | H1: 2021 | I1: 2020 | J1: 2019 | K1: 2018 | L1: ORDEM2
A2: 1 | B2: (+) RECEITA BRUTA DE VENDAS | C2: =-SUMIF(Planilha1!H:H,Export!A2,Planilha1!G:G)/1000 -> 66782.783 | D2: 183977.6 | E2: 325769.23 | F2: 352873.28 | G2: 271388.61 | H2: 237370.64 | I2: 176.025 | J2: 100.978 | K2: 88.411 | L2: 1
A3: 2 | B3: RECEITA BRUTA DE VENDAS | C3: =C2 -> 66782.783 | D3: 183977.6 | E3: 325769.23 | F3: 352873 | G3: 271389 | H3: 237370.64 | I3: 176.025 | J3: 100.978 | K3: 88.411 | L3: 2
A4: 3 | B4: (-)TRIBUTOS SOBRE VENDAS | C4: =-SUMIF(Planilha1!H:H,Export!A4,Planilha1!G:G)/1000 -> -236.92766 | D4: -10820.206 | E4: -2228.2526 | F4: =-503.5638 -> -503.5638 | G4: -2584 | H4: -577.12 | I4: 818 | J4: 6.637 | K4: 4.297 | L4: 3
A5: 4 | B5: TRIBUTOS SOBRE VENDAS | E5: -2228.2526 | F5: 504 | G5: 2584 | H5: 577 | I5: 818 | J5: 6.637 | K5: 4.297 | L5: 4
A6: 5 | B6: (=)RECEITA LÍQUIDA DE VENDAS | C6: =C2+C4 -> 66545.856 | D6: 173157.39 | E6: 323540.98 | F6: =F2+F4 -> 352369.72 | G6: =G2+G4 -> 268804.61 | H6: =H2+H4 -> 236793.52 | I6: 175.206 | J6: 94.341 | K6: 84.114 | L6: 5
A7: 6 | B7: (-)CUSTOS DOS PRODUTOS VENDIDOS | C7: =-SUMIF(Planilha1!H:H,Export!A7,Planilha1!G:G)/1000 -> -79975.318 | D7: -197381.21 | E7: -275281.46 | F7: -257478.62 | G7: -196795.18 | H7: -167565 | I7: 117.128 | J7: 92.699 | K7: 87.654 | L7: 6
A8: 7 | B8: CUSTOS DOS PRODUTOS VENDIDOS | E8: -275281.46 | F8: 257479 | G8: 196795 | H8: 167565 | I8: 117.128 | J8: 92.699 | K8: 87.654 | L8: 7
A9: 21 | B9: (-)CUSTOS DE OCIOSIDADE | C9: =-SUMIF(Planilha1!H:H,Export!A9,Planilha1!G:G)/1000 -> 0 | D9: 0 | E9: 0 | F9: -36063.36 | G9: =-27967.178 -> -27967.178 | L9: 8
A10: 8 | B10: (=)LUCRO BRUTO | C10: =C6+C7+C9 -> -13429.462 | D10: -24223.818 | E10: 48259.52 | F10: =F6+F7+F9 -> 58827.736 | G10: =G6+G7+G9 -> 44042.252 | H10: =H6+H7+H9 -> 69228.52 | I10: 58.078 | J10: 1.642 | K10: 3.540 | L10: 9
A11: 9 | B11: (-)DESPESAS E OUTRAS RECEITAS OPERACIONAIS | C11: =SUM(C12:C16) -> -10486.524 | D11: -21196.787 | E11: -22733.224 | F11: =SUM(F12:F16) -> -36151.24 | G11: =SUM(G12:G16) -> -1464.7285 | H11: =SUM(H12:H16) -> 127493.43 | I11: 19.604 | J11: 13.753 | K11: 2.162 | L11: 10
A12: 10 | B12: DESPESAS COM VENDAS | C12: =-SUMIF(Planilha1!H:H,Export!A12,Planilha1!G:G)/1000 -> -2896.0714 | D12: -10072.415 | E12: -11604.988 | F12: -13405.3 | G12: -8936.14 | H12: -6556.16 | I12: 7267 | J12: 4364 | K12: 4072 | L12: 11
A13: 11 | B13: DESPESAS GERAIS E ADMINISTRATIVAS | C13: =-SUMIF(Planilha1!H:H,Export!A13,Planilha1!G:G)/1000 -> -7856.7716 | D13: -23424.207 | E13: -28714.967 | F13: -24353.46 | G13: -22928.42 | H13: -18193.15 | I13: 13888 | J13: 12700 | K13: 18926 | L13: 12
A14: 12 | B14: OUTRAS (RECEITAS)/ DESPESAS OPERACIONAIS | C14: =-SUMIF(Planilha1!H:H,Export!A14,Planilha1!G:G)/1000 -> 435.34793 | D14: 600.92124 | E14: 5060.6991 | F14: =-34455.84+36063.36-1834444.31/1000 -> -226.92431 | G14: =--57157+27967-0.18-79201.28986 -> 5922.5301 | H14: =154481-(140390228.75)/1000 -> 14090.771 | I14: -1551 | J14: -3311 | K14: -20836 | L14: 13
A15: 23 | B15: RESULTADO DE EQUIVALÊNCIA PATRIMONIAL | C15: =-SUMIF(Planilha1!H:H,Export!A15,Planilha1!G:G)/1000 -> 0 | D15: 4849.9783 | E15: 3445.7249 | F15: =1834444.31/1000 -> 1834.4443 | G15: 0 | H15: 0 | I15: 0 | J15: 0 | K15: 0 | L15: 14
A16: 20 | B16: DESPESAS/RECEITAS NÃO RECORRENTE | C16: =-SUMIF(Planilha1!H:H,Export!A16,Planilha1!G:G)/1000 -> -169.02896 | D16: 6848.9353 | E16: 9080.3068 | F16: 0 | G16: =-(36199786.06+33088827.87+5476961.94+6650705.96)/1000+160617571.69/1000-54723.98848 -> 24477.301 | H16: =(140390228.75)/1000+22430000/1000+(-8228699.15-5305343.2)/1000-11134217.84/1000 -> 138151.97 | I16: 0 | J16: 0 | K16: 0 | L16: 15
A17: 13 | B17: (=)RESULTADO OPERACIONAL ANTES DO RESULTADO FINANCEIRO | C17: =C10+C11 -> -23915.986 | D17: -45420.605 | E17: 25526.296 | F17: =F10+F11 -> 22676.496 | G17: =G10+G11 -> 42577.524 | H17: =H10+H11 -> 196721.95 | I17: 38.474 | J17: 12.111 | K17: 5.702 | L17: 16
A18: 14 | B18: RESULTADO FINANCEIRO LÍQUIDO | C18: =-SUMIF(Planilha1!H:H,Export!A18,Planilha1!G:G)/1000 -> -3898.9236 | D18: -13173.997 | E18: -10560.316 | F18: -12486.76 | G18: =-61428.12+54723.98848 -> -6704.1315 | H18: =-31030.5-((-8228699.15-5305343.2)/1000-11134217.84/1000) -> -6362.2398 | I18: 15.204 | J18: 4.369 | K18: 4.000 | L18: 17
A19: 15 | B19: RESULTADO FINANCEIRO LIQUIDO | E19: 2938.1971 | F19: 12.488 | G19: 61428 | H19: 31031 | I19: 15.204 | J19: 4.369 | K19: 4.000 | L19: 17
A20: 16 | B20: RESULTADO ANTES DO IRPJ E CSLL | C20: =C17+C18 -> -27814.909 | D20: -58594.602 | E20: 14965.98 | F20: =F17+F18 -> 10189.736 | G20: =G17+G18 -> 35873.392 | H20: =H17+H18 -> 190359.71 | I20: 23.270 | J20: (16.480) | K20: (9.702) | L20: 18
A21: 17 | B21: IMPOSTO DE RENDA E CONTRIBUIÇÃO SOCIAL | C21: 0 | D21: 0 | E21: 0 | F21: 0 | G21: 0 | H21: 728 | I21: 147 | J21: 0 | K21: 0 | L21: 19
A22: 23 | B22: PROVISÃO PARA IR/CSLL | C22: - | D22: - | E22: - | F22: - | G22: - | H22: 728 | I22: 147 | J22: - | K22: - | L22: 20
A23: 20 | B23: RESULTADO LÍQUIDO | C23: =C20 -> -27814.909 | D23: -58594.602 | E23: 14965.98 | F23: =F20 -> 10189.736 | G23: =G20 -> 35873.392 | H23: 167202 | I23: 23.123 | J23: (16.480) | K23: (9.702) | L23: 23
A24: 22 | B24: RESULTADO LÍQUIDO - AJUSTADO | C24: =C23-C16 -> -27645.88 | D24: -65443.537 | E24: 5885.673 | F24: =F23-F16 -> 10189.736 | G24: =G23-G16 -> 11396.091 | H24: =H23-H16 -> 29050.031 | I24: =I23-I16 -> 23123 | J24: =J23-J16 -> -16480 | K24: =K23-K16 -> -9702 | L24: 25

Sheet Teste

Sheet Planilha1
A1: Balancete - Padrão - Fiscal
A2: Grupo Empresa: 1 - Santa Clotilde | G2: Data: 03/12/2025
A3: Empresa: 1 - USINA SANTA CLOTILDE | G3: Hora: 09:07:30
A4: Filial: 1 - USINA SANTA CLOTILDE S/A | G4: Form: 1016
A6: Conta contábil: 0 à 0
A7: Conta | B7: Descrição | C7: Saldo Anterior | D7: Débitos | E7: Créditos | F7: Saldo Mensal | G7: Saldo
A8: 3 | B8: RESULTADO DO EXERCÍCIO | C8: 25301531 | D8: 20898594 | E8: 18385216 | F8: 2513378.7 | G8: 27814909 | H8: =_xlfn.XLOOKUP(A8,indice!A:A,indice!C:C) -> S
A9: 3.1 | B9: RECEITAS BRUTA DE VENDAS | C9: -58132400 | D9: 60797.28 | E9: 8711180.6 | F9: -8650383.4 | G9: -66782783 | H9: =_xlfn.XLOOKUP(A9,indice!A:A,indice!C:C) -> S
A10: 3.1.1 | B10: VENDAS DE PRODUÇÃO PRÓPRIA | C10: -58132400 | D10: 60797.28 | E10: 8711180.6 | F10: -8650383.4 | G10: -66782783 | H10: =_xlfn.XLOOKUP(A10,indice!A:A,indice!C:C) -> S
A11: 3.1.1.01 | B11: VENDAS NO MERCADO INTERNO | C11: -25540961 | D11: 0 | E11: 0 | F11: 0 | G11: -25540961 | H11: =_xlfn.XLOOKUP(A11,indice!A:A,indice!C:C) -> S
A12: 3.1.1.01.003 | B12: MELAÇO | C12: -76992 | D12: 0 | E12: 0 | F12: 0 | G12: -76992 | H12: =_xlfn.XLOOKUP(A12,indice!A:A,indice!C:C) -> 1
A13: 3.1.1.01.005 | B13: ÁLCOOL ANIDRO | C13: -9024205.4 | D13: 0 | E13: 0 | F13: 0 | G13: -9024205.4 | H13: =_xlfn.XLOOKUP(A13,indice!A:A,indice!C:C) -> 1
A14: 3.1.1.01.006 | B14: ÁLCOOL HIDRATADO | C14: -13061965 | D14: 0 | E14: 0 | F14: 0 | G14: -13061965 | H14: =_xlfn.XLOOKUP(A14,indice!A:A,indice!C:C) -> 1
A15: 3.1.1.01.007 | B15: AÇÚCAR VHP | C15: -3377798.6 | D15: 0 | E15: 0 | F15: 0 | G15: -3377798.6 | H15: =_xlfn.XLOOKUP(A15,indice!A:A,indice!C:C) -> 1
A16: 3.1.1.02 | B16: VENDAS NO MERCADO EXTERNO | C16: -32400989 | D16: 0 | E16: 7961824.4 | F16: -7961824.4 | G16: -40362813 | H16: =_xlfn.XLOOKUP(A16,indice!A:A,indice!C:C) -> S
A17: 3.1.1.02.007 | B17: AÇÚCAR VHP | C17: -32400989 | D17: 0 | E17: 7961824.4 | F17: -7961824.4 | G17: -40362813 | H17: =_xlfn.XLOOKUP(A17,indice!A:A,indice!C:C) -> 1
A18: 3.1.1.03 | B18: VENDA DE SUB-PRODUTO | C18: -4290 | D18: 0 | E18: 1170 | F18: -1170 | G18: -5460 | H18: =_xlfn.XLOOKUP(A18,indice!A:A,indice!C:C) -> S
A19: 3.1.1.03.002 | B19: ÓLEO FUSEL | C19: -4290 | D19: 0 | E19: 1170 | F19: -1170 | G19: -5460 | H19: =_xlfn.XLOOKUP(A19,indice!A:A,indice!C:C) -> 1
... A201: 3.2.3.06.002 | B201: RECEITA DA ALIENAÇÃO DE IMOBILIZADO | C201: -70000 | D201: 0 | E201: 0 | F201: 0 | G201: -70000 | H201: =_xlfn.XLOOKUP(A201,indice!A:A,indice!C:C) -> 12
D202: 1.0100534e+08 | E202: 1.0100534e+08

Sheet indice
A1: 3 | B1: RESULTADO DO EXERCÍCIO | C1: S | D1: SINTETICA
A2: 3.1 | B2: RECEITAS BRUTA DE VENDAS | C2: S | D2: SINTETICA
A3: 3.1.1 | B3: VENDAS DE PRODUÇÃO PRÓPRIA | C3: S | D3: SINTETICA
A4: 3.1.1.01 | B4: VENDAS NO MERCADO INTERNO | C4: S | D4: SINTETICA
A5: 3.1.1.01.003 | B5: MELAÇO | C5: 1 | D5: (+) RECEITA BRUTA DE VENDAS
A6: 3.1.1.01.004 | B6: AÇÚCAR CRISTAL | C6: 1 | D6: (+) RECEITA BRUTA DE VENDAS
A7: 3.1.1.01.005 | B7: ÁLCOOL ANIDRO | C7: 1 | D7: (+) RECEITA BRUTA DE VENDAS
A8: 3.1.1.01.006 | B8: ÁLCOOL HIDRATADO | C8: 1 | D8: (+) RECEITA BRUTA DE VENDAS
A9: 3.1.1.01.007 | B9: AÇÚCAR VHP | C9: 1 | D9: (+) RECEITA BRUTA DE VENDAS
A10: 3.1.1.02 | B10: VENDAS NO MERCADO EXTERNO | C10: S | D10: SINTETICA
A11: 3.1.1.02.007 | B11: AÇÚCAR VHP | C11: 1 | D11: (+) RECEITA BRUTA DE VENDAS
A12: 3.1.1.03 | B12: VENDA DE SUB-PRODUTO | C12: S | D12: SINTETICA
A13: 3.1.1.03.001 | B13: BAGAÇO | C13: 1 | D13: (+) RECEITA BRUTA DE VENDAS
A14: 3.1.1.03.002 | B14: ÓLEO FUSEL | C14: 1 | D14: (+) RECEITA BRUTA DE VENDAS
A15: 3.1.1.04 | B15: VENDA DE PRODUTOS AGRÍCOLAS | C15: S | D15: SINTETICA
A16: 3.1.1.04.001 | B16: CANA DE AÇUCAR | C16: 1 | D16: (+) RECEITA BRUTA DE VENDAS
A17: 3.1.1.05 | B17: OUTRAS RECEITAS COM VENDAS DE MERCADORIAS | C17: S | D17: SINTETICA
A18: 3.1.1.05.001 | B18: VENDA DE SUCATA | C18: 1 | D18: (+) RECEITA BRUTA DE VENDAS
A19: 3.1.1.05.002 | B19: VENDAS DE ALMOXARIFADO | C19: 1 | D19: (+) RECEITA BRUTA DE VENDAS
A20: 3.1.1.06 | B20: RECEITAS S/ SERVIÇOS | C20: S | D20: SINTETICA
A21: 3.1.1.06.002 | B21: RECEITAS S/SERVIÇOS | C21: 1 | D21: (+) RECEITA BRUTA DE VENDAS
A22: 3.2 | B22: DEDUÇÕES DE CUSTOS E DESP.OPERACIONAIS | C22: S | D22: SINTETICA
A23: 3.2.1 | B23: DEDUÇÕES DIVERSAS | C23: S | D23: SINTETICA
A24: 3.2.1.01 | B24: IMPOSTOS INCIDENTES SOBRE AS VENDAS DE PRODUTOS | C24: S | D24: SINTETICA
A25: 3.2.1.01.001 | B25: ICMS | C25: 3 | D25: (-)TRIBUTOS SOBRE VENDAS
A26: 3.2.1.01.002 | B26: IPI | C26: 3 | D26: (-)TRIBUTOS SOBRE VENDAS
A27: 3.2.1.01.003 | B27: PIS S/FATURAMENTO | C27: 3 | D27: (-)TRIBUTOS SOBRE VENDAS
A28: 3.2.1.01.004 | B28: COFINS S/FATURAMENTO | C28: 3 | D28: (-)TRIBUTOS SOBRE VENDAS
A29: 3.2.1.01.005 | B29: INSS S/FATURAMENTO | C29: 3 | D29: (-)TRIBUTOS SOBRE VENDAS
A30: 3.2.1.01.006 | B30: ICMS ST | C30: 3 | D30: (-)TRIBUTOS SOBRE VENDAS
A31: 3.2.1.03 | B31: IMPOSTOS INCIDENTES SOBRE AS DEMAIS VENDAS | C31: S | D31: SINTETICA
A32: 3.2.1.03.001 | B32: ICMS | C32: 3 | D32: (-)TRIBUTOS SOBRE VENDAS
A33: 3.2.1.03.003 | B33: PIS S/ FATURAMENTO | C33: 3 | D33: (-)TRIBUTOS SOBRE VENDAS
A34: 3.2.1.03.004 | B34: COFINS S/ FATURAMENTO | C34: 3 | D34: (-)TRIBUTOS SOBRE VENDAS
A35: 3.2.2 | B35: CUSTOS DOS PRODUTOS VENDIDOS | C35: S | D35: SINTETICA
A36: 3.2.2.01 | B36: CUSTOS DIVERSOS | C36: S | D36: SINTETICA
A37: 3.2.2.01.001 | B37: AÇÚCAR | C37: 6 | D37: (-)CUSTOS DOS PRODUTOS VENDIDOS
A38: 3.2.2.01.002 | B38: ÁLCOOL | C38: 6 | D38: (-)CUSTOS DOS PRODUTOS VENDIDOS
A39: 3.2.2.01.003 | B39: MELAÇO | C39: 6 | D39: (-)CUSTOS DOS PRODUTOS VENDIDOS
A40: 3.2.2.01.004 | B40: ETANOL ANIDRO | C40: 6 | D40: (-)CUSTOS DOS PRODUTOS VENDIDOS
...
